<?xml version="1.0" encoding="utf-8"?>
<!-- This URDF was automatically created by SolidWorks to URDF Exporter! Originally created by Stephen Brawner (brawner@gmail.com) 
     Commit Version: 1.5.1-0-g916b5db  Build Version: 1.5.7152.31018
     For more information, please see http://wiki.ros.org/sw_urdf_exporter -->
<robot
  name="assembly_urdf">
  <link
    name="base_link">
    <inertial>
      <origin
        xyz="-1.88332288303835E-05 0.335041830979376 0.0672559512927368"
        rpy="0 0 0" />
      <mass
        value="2.50216732502463" />
      <inertia
        ixx="0.0653823275083831"
        ixy="1.06934829883648E-05"
        ixz="-1.98536691802048E-08"
        iyy="0.00548013594659747"
        iyz="-8.39676001019919E-09"
        izz="0.0665700447223665" />
    </inertial>
    <visual>
      <origin
        xyz="0 0 0"
        rpy="0 0 0" />
      <geometry>
        <mesh
          filename="package://assembly_urdf/meshes/base_link.STL" />
      </geometry>
      <material
        name="">
        <color
          rgba="0.964705882352941 0.964705882352941 0.952941176470588 1" />
      </material>
    </visual>
    <collision>
      <origin
        xyz="0 0 0"
        rpy="0 0 0" />
      <geometry>
        <mesh
          filename="package://assembly_urdf/meshes/base_link.STL" />
      </geometry>
    </collision>
  </link>
  <link
    name="shaft_link1">
    <inertial>
      <origin
        xyz="-2.28346780373201E-08 0.0862779061401729 -0.000639254948745727"
        rpy="0 0 0" />
      <mass
        value="0.046919956660997" />
      <inertia
        ixx="0.000119663056281602"
        ixy="-3.38099444967384E-11"
        ixz="1.86974367336289E-11"
        iyy="2.34114622141712E-06"
        iyz="-9.48476256333392E-08"
        izz="0.000119826953022065" />
    </inertial>
    <visual>
      <origin
        xyz="0 0 0"
        rpy="0 0 0" />
      <geometry>
        <mesh
          filename="package://assembly_urdf/meshes/shaft_link1.STL" />
      </geometry>
      <material
        name="">
        <color
          rgba="0.627450980392157 0.627450980392157 0.627450980392157 1" />
      </material>
    </visual>
    <collision>
      <origin
        xyz="0 0 0"
        rpy="0 0 0" />
      <geometry>
        <mesh
          filename="package://assembly_urdf/meshes/shaft_link1.STL" />
      </geometry>
    </collision>
  </link>
  <joint
    name="motor_link1"
    type="revolute">
    <origin
      xyz="0.085 -0.067256 0.56196"
      rpy="1.5708 -1.5708 0" />
    <parent
      link="base_link" />
    <child
      link="shaft_link1" />
    <axis
      xyz="0 0 0" />
    <limit
      lower="-1.5708"
      upper="1.5708"
      effort="0"
      velocity="0" />
  </joint>
  <link
    name="Link_2">
    <inertial>
      <origin
        xyz="-0.000260501589222445 -0.00418554305359831 -1.76151432450949E-08"
        rpy="0 0 0" />
      <mass
        value="2.23900935342226" />
      <inertia
        ixx="0.00651527634561222"
        ixy="1.82478627012723E-05"
        ixz="3.75604928471886E-09"
        iyy="0.00499823395365336"
        iyz="-1.44186921284753E-08"
        izz="0.00754178994678366" />
    </inertial>
    <visual>
      <origin
        xyz="0 0 0"
        rpy="0 0 0" />
      <geometry>
        <mesh
          filename="package://assembly_urdf/meshes/Link_2.STL" />
      </geometry>
      <material
        name="">
        <color
          rgba="0.964705882352941 0.964705882352941 0.952941176470588 1" />
      </material>
    </visual>
    <collision>
      <origin
        xyz="0 0 0"
        rpy="0 0 0" />
      <geometry>
        <mesh
          filename="package://assembly_urdf/meshes/Link_2.STL" />
      </geometry>
    </collision>
  </link>
  <joint
    name="pitch_link"
    type="revolute">
    <origin
      xyz="0.00028402 -0.060596 0.71296"
      rpy="-1.5708 0 -1.5708" />
    <parent
      link="base_link" />
    <child
      link="Link_2" />
    <axis
      xyz="0 0 0" />
    <limit
      lower="-1.5708"
      upper="1.5708"
      effort="0"
      velocity="0" />
  </joint>
  <link
    name="shaft_link2">
    <inertial>
      <origin
        xyz="-2.28346784814093E-08 0.0862779061401616 -0.000639254948745162"
        rpy="0 0 0" />
      <mass
        value="0.0469199566610044" />
      <inertia
        ixx="0.000119663056281604"
        ixy="-3.38099442054279E-11"
        ixz="1.86974367409058E-11"
        iyy="2.3411462214172E-06"
        iyz="-9.48476256329531E-08"
        izz="0.000119826953022066" />
    </inertial>
    <visual>
      <origin
        xyz="0 0 0"
        rpy="0 0 0" />
      <geometry>
        <mesh
          filename="package://assembly_urdf/meshes/shaft_link2.STL" />
      </geometry>
      <material
        name="">
        <color
          rgba="0.627450980392157 0.627450980392157 0.627450980392157 1" />
      </material>
    </visual>
    <collision>
      <origin
        xyz="0 0 0"
        rpy="0 0 0" />
      <geometry>
        <mesh
          filename="package://assembly_urdf/meshes/shaft_link2.STL" />
      </geometry>
    </collision>
  </link>
  <joint
    name="motor_link2"
    type="revolute">
    <origin
      xyz="0.085 -0.18 0"
      rpy="0 0 1.5708" />
    <parent
      link="Link_2" />
    <child
      link="shaft_link2" />
    <axis
      xyz="0 0 0" />
    <limit
      lower="-1.5708"
      upper="1.5708"
      effort="0"
      velocity="0" />
    <mimic
      joint="motor_link3"
      multiplier="1"
      offset="0" />
  </joint>
  <link
    name="link_3">
    <inertial>
      <origin
        xyz="0.00894239401770391 0.000280508075083915 -4.84079033715931E-05"
        rpy="0 0 0" />
      <mass
        value="0.973698526007838" />
      <inertia
        ixx="0.00203345368620413"
        ixy="-4.15867011984283E-06"
        ixz="-4.19134011282035E-06"
        iyy="0.00419113796679173"
        iyz="-1.30677423529018E-08"
        izz="0.00294630958867532" />
    </inertial>
    <visual>
      <origin
        xyz="0 0 0"
        rpy="0 0 0" />
      <geometry>
        <mesh
          filename="package://assembly_urdf/meshes/link_3.STL" />
      </geometry>
      <material
        name="">
        <color
          rgba="0.964705882352941 0.964705882352941 0.952941176470588 1" />
      </material>
    </visual>
    <collision>
      <origin
        xyz="0 0 0"
        rpy="0 0 0" />
      <geometry>
        <mesh
          filename="package://assembly_urdf/meshes/link_3.STL" />
      </geometry>
    </collision>
  </link>
  <joint
    name="yaw_link"
    type="revolute">
    <origin
      xyz="-0.0013889 -0.060856 0.96396"
      rpy="0.2264 1.5708 -1.3444" />
    <parent
      link="base_link" />
    <child
      link="link_3" />
    <axis
      xyz="0 0 0" />
    <limit
      lower="-1.5708"
      upper="1.5708"
      effort="0"
      velocity="0" />
  </joint>
  <link
    name="shaft_link3">
    <inertial>
      <origin
        xyz="-2.2834678370387E-08 0.0862779061401833 -0.000639254945797905"
        rpy="0 0 0" />
      <mass
        value="0.0469199566610044" />
      <inertia
        ixx="0.000119663056281604"
        ixy="-3.38099445682339E-11"
        ixz="1.86974367587241E-11"
        iyy="2.34114622142368E-06"
        iyz="-9.48476296462588E-08"
        izz="0.000119826953022059" />
    </inertial>
    <visual>
      <origin
        xyz="0 0 0"
        rpy="0 0 0" />
      <geometry>
        <mesh
          filename="package://assembly_urdf/meshes/shaft_link3.STL" />
      </geometry>
      <material
        name="">
        <color
          rgba="0.627450980392157 0.627450980392157 0.627450980392157 1" />
      </material>
    </visual>
    <collision>
      <origin
        xyz="0 0 0"
        rpy="0 0 0" />
      <geometry>
        <mesh
          filename="package://assembly_urdf/meshes/shaft_link3.STL" />
      </geometry>
    </collision>
  </link>
  <joint
    name="motor_link3"
    type="revolute">
    <origin
      xyz="-0.08 0 0.085"
      rpy="-1.5708 0 0" />
    <parent
      link="link_3" />
    <child
      link="shaft_link3" />
    <axis
      xyz="0 0 0" />
    <limit
      lower="-1.5708"
      upper="1.5708"
      effort="0"
      velocity="0" />
    <mimic
      joint="motor_link2"
      multiplier="1"
      offset="0" />
  </joint>
  <link
    name="gripper_link">
    <inertial>
      <origin
        xyz="0.0216976226907989 -0.122547144464517 0.0814178968871869"
        rpy="0 0 0" />
      <mass
        value="0.822220892683325" />
      <inertia
        ixx="0.00271143118949264"
        ixy="7.85142372267252E-05"
        ixz="-3.38432825835257E-07"
        iyy="0.00174277915122272"
        iyz="1.08542481244002E-06"
        izz="0.00120037814165339" />
    </inertial>
    <visual>
      <origin
        xyz="0 0 0"
        rpy="0 0 0" />
      <geometry>
        <mesh
          filename="package://assembly_urdf/meshes/gripper_link.STL" />
      </geometry>
      <material
        name="">
        <color
          rgba="0.964705882352941 0.964705882352941 0.952941176470588 1" />
      </material>
    </visual>
    <collision>
      <origin
        xyz="0 0 0"
        rpy="0 0 0" />
      <geometry>
        <mesh
          filename="package://assembly_urdf/meshes/gripper_link.STL" />
      </geometry>
    </collision>
  </link>
  <joint
    name="gripper_movement"
    type="revolute">
    <origin
      xyz="-0.02769 0.018952 1.2402"
      rpy="1.5708 0 0" />
    <parent
      link="base_link" />
    <child
      link="gripper_link" />
    <axis
      xyz="0 0 0" />
    <limit
      lower="-1.5708"
      upper="1.5708"
      effort="0"
      velocity="0" />
  </joint>
</robot>