<?xml version="1.0" encoding="utf-8"?>
<!-- This URDF was automatically created by SolidWorks to URDF Exporter! Originally created by Stephen Brawner (brawner@gmail.com) 
     Commit Version: 1.5.1-0-g916b5db  Build Version: 1.5.7152.31018
     For more information, please see http://wiki.ros.org/sw_urdf_exporter -->
<robot
  name="Assembly_URDF v6">
  <link
    name="base_link">
    <inertial>
      <origin
        xyz="-1.88332288303831E-05 0.163077243139101 -2.01206812296738E-08"
        rpy="0 0 0" />
      <mass
        value="2.50216732502464" />
      <inertia
        ixx="0.0653823275083831"
        ixy="1.06934829883646E-05"
        ixz="-1.98536691802712E-08"
        iyy="0.00548013594659747"
        iyz="-8.39676000995102E-09"
        izz="0.0665700447223665" />
    </inertial>
    <visual>
      <origin
        xyz="0 0 0"
        rpy="0 0 0" />
      <geometry>
        <mesh
          filename="package://Assembly_URDF v6/meshes/base_link.STL" />
      </geometry>
      <material
        name="">
        <color
          rgba="0.964705882352941 0.964705882352941 0.952941176470588 1" />
      </material>
    </visual>
    <collision>
      <origin
        xyz="0 0 0"
        rpy="0 0 0" />
      <geometry>
        <mesh
          filename="package://Assembly_URDF v6/meshes/base_link.STL" />
      </geometry>
    </collision>
  </link>
  <link
    name="shaft_Link1">
    <inertial>
      <origin
        xyz="-2.28346780373201E-08 0.0862779061401731 -0.000639254948745765"
        rpy="0 0 0" />
      <mass
        value="0.0469199566609967" />
      <inertia
        ixx="0.000119663056281602"
        ixy="-3.38099445013419E-11"
        ixz="1.86974367383666E-11"
        iyy="2.3411462214171E-06"
        iyz="-9.48476256334187E-08"
        izz="0.000119826953022064" />
    </inertial>
    <visual>
      <origin
        xyz="0 0 0"
        rpy="0 0 0" />
      <geometry>
        <mesh
          filename="package://Assembly_URDF v6/meshes/shaft_Link1.STL" />
      </geometry>
      <material
        name="">
        <color
          rgba="0.627450980392157 0.627450980392157 0.627450980392157 1" />
      </material>
    </visual>
    <collision>
      <origin
        xyz="0 0 0"
        rpy="0 0 0" />
      <geometry>
        <mesh
          filename="package://Assembly_URDF v6/meshes/shaft_Link1.STL" />
      </geometry>
    </collision>
  </link>
  <joint
    name="motor_1"
    type="revolute">
    <origin
      xyz="0.085 0 0.39"
      rpy="1.5708 -1.5708 0" />
    <parent
      link="base_link" />
    <child
      link="shaft_Link1" />
    <axis
      xyz="0 0 0" />
    <limit
      lower="-1.5708"
      upper="1.5708"
      effort="0"
      velocity="0" />
  </joint>
  <link
    name="Link_2">
    <inertial>
      <origin
        xyz="-0.00026050158922244 -0.00418554305359831 -1.76151432506244E-08"
        rpy="0 0 0" />
      <mass
        value="2.23900935342226" />
      <inertia
        ixx="0.00651527634561222"
        ixy="1.82478627012732E-05"
        ixz="3.75604928548178E-09"
        iyy="0.00499823395365336"
        iyz="-1.44186921277552E-08"
        izz="0.00754178994678366" />
    </inertial>
    <visual>
      <origin
        xyz="0 0 0"
        rpy="0 0 0" />
      <geometry>
        <mesh
          filename="package://Assembly_URDF v6/meshes/Link_2.STL" />
      </geometry>
      <material
        name="">
        <color
          rgba="0.964705882352941 0.964705882352941 0.952941176470588 1" />
      </material>
    </visual>
    <collision>
      <origin
        xyz="0 0 0"
        rpy="0 0 0" />
      <geometry>
        <mesh
          filename="package://Assembly_URDF v6/meshes/Link_2.STL" />
      </geometry>
    </collision>
  </link>
  <joint
    name="pitch movement"
    type="revolute">
    <origin
      xyz="0.00028402 0.0066603 0.541"
      rpy="-1.5708 0 -1.5708" />
    <parent
      link="base_link" />
    <child
      link="Link_2" />
    <axis
      xyz="0 0 0" />
    <limit
      lower="-1.5708"
      upper="1.5708"
      effort="0"
      velocity="0" />
  </joint>
  <link
    name="shaft_link2">
    <inertial>
      <origin
        xyz="-2.28346784814093E-08 0.0862779061401617 -0.000639254948745175"
        rpy="0 0 0" />
      <mass
        value="0.0469199566610043" />
      <inertia
        ixx="0.000119663056281604"
        ixy="-3.38099442568599E-11"
        ixz="1.86974367557585E-11"
        iyy="2.3411462214172E-06"
        iyz="-9.4847625632997E-08"
        izz="0.000119826953022066" />
    </inertial>
    <visual>
      <origin
        xyz="0 0 0"
        rpy="0 0 0" />
      <geometry>
        <mesh
          filename="package://Assembly_URDF v6/meshes/shaft_link2.STL" />
      </geometry>
      <material
        name="">
        <color
          rgba="0.627450980392157 0.627450980392157 0.627450980392157 1" />
      </material>
    </visual>
    <collision>
      <origin
        xyz="0 0 0"
        rpy="0 0 0" />
      <geometry>
        <mesh
          filename="package://Assembly_URDF v6/meshes/shaft_link2.STL" />
      </geometry>
    </collision>
  </link>
  <joint
    name="motor_2"
    type="revolute">
    <origin
      xyz="0.085 -0.18 0"
      rpy="0 0 1.5708" />
    <parent
      link="Link_2" />
    <child
      link="shaft_link2" />
    <axis
      xyz="0 0 0" />
    <limit
      lower="-1.57079633"
      upper="1.57079633"
      effort="0"
      velocity="0" />
  </joint>
  <link
    name="Link_3">
    <inertial>
      <origin
        xyz="0.00894239401770391 0.000280508075083926 -4.84079033716122E-05"
        rpy="0 0 0" />
      <mass
        value="0.973698526007838" />
      <inertia
        ixx="0.00203345368620413"
        ixy="-4.15867011984317E-06"
        ixz="-4.19134011282013E-06"
        iyy="0.00419113796679174"
        iyz="-1.30677423527313E-08"
        izz="0.00294630958867532" />
    </inertial>
    <visual>
      <origin
        xyz="0 0 0"
        rpy="0 0 0" />
      <geometry>
        <mesh
          filename="package://Assembly_URDF v6/meshes/Link_3.STL" />
      </geometry>
      <material
        name="">
        <color
          rgba="0.964705882352941 0.964705882352941 0.952941176470588 1" />
      </material>
    </visual>
    <collision>
      <origin
        xyz="0 0 0"
        rpy="0 0 0" />
      <geometry>
        <mesh
          filename="package://Assembly_URDF v6/meshes/Link_3.STL" />
      </geometry>
    </collision>
  </link>
  <joint
    name="yaw movement"
    type="revolute">
    <origin
      xyz="-0.0013889 0.0063996 0.792"
      rpy="0.2264 1.5708 -1.3444" />
    <parent
      link="base_link" />
    <child
      link="Link_3" />
    <axis
      xyz="0 0 0" />
    <limit
      lower="-1.57079633"
      upper="1.57079633"
      effort="0"
      velocity="0" />
    <mimic
      joint="yaw_move"
      multiplier="1"
      offset="0" />
  </joint>
  <link
    name="shaft_link3">
    <inertial>
      <origin
        xyz="-2.28346782593647E-08 0.0862779061401836 -0.000639254945797939"
        rpy="0 0 0" />
      <mass
        value="0.0469199566610041" />
      <inertia
        ixx="0.000119663056281603"
        ixy="-3.38099444190241E-11"
        ixz="1.86974367326263E-11"
        iyy="2.34114622142366E-06"
        iyz="-9.48476296463714E-08"
        izz="0.000119826953022059" />
    </inertial>
    <visual>
      <origin
        xyz="0 0 0"
        rpy="0 0 0" />
      <geometry>
        <mesh
          filename="package://Assembly_URDF v6/meshes/shaft_link3.STL" />
      </geometry>
      <material
        name="">
        <color
          rgba="0.627450980392157 0.627450980392157 0.627450980392157 1" />
      </material>
    </visual>
    <collision>
      <origin
        xyz="0 0 0"
        rpy="0 0 0" />
      <geometry>
        <mesh
          filename="package://Assembly_URDF v6/meshes/shaft_link3.STL" />
      </geometry>
    </collision>
  </link>
  <joint
    name="motor_3"
    type="revolute">
    <origin
      xyz="-0.08 0 0.085"
      rpy="-1.5708 0 0" />
    <parent
      link="Link_3" />
    <child
      link="shaft_link3" />
    <axis
      xyz="0 0 0" />
    <limit
      lower="-1.5708"
      upper="1.5708"
      effort="0"
      velocity="0" />
    <mimic
      joint="motor_2"
      multiplier="1"
      offset="0" />
  </joint>
  <link
    name="Gripper_link">
    <inertial>
      <origin
        xyz="0.0216976226908029 -0.122547144464513 0.0814178968872003"
        rpy="0 0 0" />
      <mass
        value="0.822220892683506" />
      <inertia
        ixx="0.00271143118949349"
        ixy="7.85142372268063E-05"
        ixz="-3.38432826092458E-07"
        iyy="0.00174277915122354"
        iyz="1.08542481268539E-06"
        izz="0.00120037814165359" />
    </inertial>
    <visual>
      <origin
        xyz="0 0 0"
        rpy="0 0 0" />
      <geometry>
        <mesh
          filename="package://Assembly_URDF v6/meshes/Gripper_link.STL" />
      </geometry>
      <material
        name="">
        <color
          rgba="0.964705882352941 0.964705882352941 0.952941176470588 1" />
      </material>
    </visual>
    <collision>
      <origin
        xyz="0 0 0"
        rpy="0 0 0" />
      <geometry>
        <mesh
          filename="package://Assembly_URDF v6/meshes/Gripper_link.STL" />
      </geometry>
    </collision>
  </link>
  <joint
    name="yaw_move"
    type="revolute">
    <origin
      xyz="-0.02769 0.086208 1.0682"
      rpy="1.5708 0 0" />
    <parent
      link="base_link" />
    <child
      link="Gripper_link" />
    <axis
      xyz="0 0 0" />
    <limit
      lower="-1.5708"
      upper="1.5708"
      effort="0"
      velocity="0" />
    <mimic
      joint="yaw movement"
      multiplier="1"
      offset="0" />
  </joint>
</robot>